<?xml version='1.0'?>
<sdf version='1.5'>
  <model name='prueba'>
    <pose>3.14696 -4.95564 1.37792 0 -0 0</pose>
    <link name='defaultModel_1::custom_2'>
      <pose>-0.051115 -0.316167 -0.877918 0 -0 0</pose>
      <gravity>1</gravity>
      <self_collide>0</self_collide>
      <kinematic>0</kinematic>
      <visual name='custom_2_visual'>
        <pose>0 0 0 0 -0 0</pose>
        <geometry>
          <mesh>
            <uri>/home/andresjhe/Blender/model.dae</uri>
            <scale>1 1 1</scale>
          </mesh>
        </geometry>
        <material>
          <script>
            <uri>file://media/materials/scripts/gazebo.material</uri>
            <name>Gazebo/Grey</name>
          </script>
        </material>
      </visual>
      <collision name='defaultModel_1::custom_2_collision'>
        <geometry>
          <mesh>
            <uri>/home/andresjhe/Blender/model.dae</uri>
            <scale>1 1 1</scale>
          </mesh>
        </geometry>
        <pose>0 0 0 0 -0 0</pose>
      </collision>
    </link>
    <link name='unit_box_4'>
      <pose>0.051115 0.316167 0.877918 0 -0 0</pose>
      <gravity>1</gravity>
      <self_collide>0</self_collide>
      <kinematic>0</kinematic>
      <visual name='unit_box_4_visual'>
        <pose>0 0 0 0 -0 0</pose>
        <geometry>
          <box>
            <size>1.4884 1.23388 0.028503</size>
          </box>
        </geometry>
        <material>
          <script>
            <uri>file://media/materials/scripts/gazebo.material</uri>
            <name>Gazebo/Grey</name>
          </script>
        </material>
      </visual>
      <collision name='unit_box_4_collision'>
        <geometry>
          <box>
            <size>1.4884 1.23388 0.028503</size>
          </box>
        </geometry>
        <pose>0 0 0 0 -0 0</pose>
      </collision>
    </link>
    <joint name='defaultModel_1::custom_2_JOINT_4' type='screw'>
      <parent>defaultModel_1::custom_2</parent>
      <child>unit_box_4</child>
      <axis>
        <xyz>1 0 0</xyz>
        <use_parent_model_frame>0</use_parent_model_frame>
        <limit>
          <lower>-3.14</lower>
          <upper>3.14</upper>
        </limit>
      </axis>
      <pose>0 0 0 0 -0 0</pose>
    </joint>
    <static>1</static>
    <allow_auto_disable>1</allow_auto_disable>
  </model>
</sdf>
